Workbook

Sheet Read Me
A1: Acra Lending — Standard DSCR Program
A2: Underwriting Sizer | Built from: Acra_DSCR_Standard_Consolidated_Guidelines_v1_0.pdf (Version 1.0, Sept 2026)
A4: What this tool is
B5: This workbook sizes a loan against Acra Lending's Standard (Business Purpose) DSCR program as described in the
B6: consolidated guidelines document supplied. It computes the calculated DSCR, walks every CLTV cap, minimum-FICO
B7: trigger, minimum-DSCR trigger and reserve trigger that the guidelines state, and returns a maximum loan amount
B8: and a pass/fail eligibility read-out.
B10: IMPORTANT — this source document is itself a draft submitted to Acra Lending for confirmation. It contains 27
B11: open questions ("Q-01" through "Q-27") where the guidelines are silent, unclear, or state two different rules.
B12: Wherever this sizer had to pick an approach to build a working formula, that choice is documented in the
B13: 'Assumptions & Open Items' tab, tagged back to the relevant Q-number. Do not treat this sizer as a substitute for
B14: Acra's underwriting sign-off — treat it as a pre-screen that flags where a human underwriter (or Acra confirmation)
B15: is required.
A17: How to use it
B18: 1. Open the 'Inputs' tab. Fill in every blue cell (yellow-filled). Dropdowns are provided where the guideline
B19: defines a fixed set of categories.
B20: 2. Open the 'Sizer' tab. Every value there is a formula — nothing to type. It shows:
B21: • the calculated DSCR and its inputs
B22: • every CLTV cap that applies to your scenario and the binding (lowest) one
B23: • the minimum DSCR, minimum FICO and reserve months your scenario triggers
B24: • the resulting maximum loan amount and a PASS/FAIL test against what was requested
B25: • a flags & notes panel for conditions the guidelines require but that aren't a simple numeric cap
B26: 3. Check the 'Flags & Notes' panel at the bottom of the Sizer tab and the 'Assumptions & Open Items' tab before
B27: relying on the output.
B28: 4. 'Reference Tables' holds every matrix, table and lookup transcribed from the guidelines, cited to its STD-
B29: paragraph. The Sizer pulls from these tables; edit them only if Acra corrects a published figure.
A31: Color legend
B32: Yellow fill, blue bold text — Input cell — type your scenario data here
B33: Black text — Formula — calculated automatically, do not overtype
B34: Green fill — Test passed
B35: Red fill — Test failed
B36: Amber fill — Requires manual review / Acra confirmation
A38: Scope and limits of this sizer
B39: • Covers the Standard DSCR matrix, DSCR/No-Ratio qualification, borrower-citizenship caps, credit-history caps,
B40: property-type caps, vacant-property and listed-for-sale refinance rules, short-term rental, first-time
B41: homebuyer, escrow waiver, rural/unique and mixed-use overlays, and the reserve triggers stated in the guide.
B42: • Does NOT automate: state-by-state prepayment penalty selection (shown for reference only — see Q-24 on what
B43: 'BUY-OUT' requires), entity/trust/guarantor documentation checklists, foreign-national closing-document and
B44: AML/OFAC requirements, gift-fund seasoning documentation, or DTI-program alternatives (Q-14) — these remain
B45: manual underwriting steps and are called out as flags where they intersect with the sizer's numeric output.
...

Sheet Inputs
A1: Loan Scenario Inputs
A2: Fill in every yellow cell. Dropdowns list the categories the guidelines define.
A4: 1. Transaction
B5: Transaction Purpose | C5: Purchase | D5: S: matrix columns
B6: Loan Amount Requested ($) | C6: 900000 | D6: S: Loan Amount ($100,000-$3,000,000, $50 increments)
B7: As-Is Value / Purchase Price ($) | C7: 700000 | D7: Used to test CLTV
B8: Subject Property State (2-letter) | C8: CA | D8: S: Subject Property Location — SD ineligible
B9: Delayed Financing? | C9: N | D9: STD-1.4 — capped at $1.5MM; column/cash-in-hand rule per Q-06
A11: 2. Borrower
B12: Borrower Citizenship | C12: US Citizen | D12: S: Borrower Citizenship
B13: Entity Borrower? | C13: N | D13: G §3.12 — triggers entity/guarantor documentation, STD-6.x
B14: First-Time Homebuyer (all borrowers)? | C14: N | D14: G §3.13; S: Restrictions
B15: Decisioning FICO Score | C15: 720 | D15: Which score governs is open — Q-19
B16: Number of Credit Bureau Scores Reported | C16: 3 | D16: S: Credit Requirements
B17: If ≤ 2 scores: tradeline overlay met? (2TL/24mo or 3TL/12mo) | C17: N/A | D17: STD-7.2 — leave N/A if 3 scores reported
A19: 3. Credit History
B20: Mortgage / Rental Housing History | C20: Clean / No Restriction | D20: S: Housing History & PCEs (labels undefined — Q-05)
B21: Bankruptcy / Foreclosure Seasoning | C21: N/A - None | D21: S: Housing History & PCEs
B22: Short Sale / Deed-in-Lieu / Modification Seasoning | C22: N/A - None | D22: S: Housing History & PCEs
B23: Forbearance/late in last 12mo AND tenant-occupied without timely 2-mo rent receipt? | C23: N | D23: G §5.32 — STD-3.15; applies to guarantors per Q-20
A25: 4. Property
B26: Property Type | C26: SFR | D26: S: Subject Property Type
B27: Florida Property? | C27: N | D27: -5% CLTV adj. on Non-Warr. Condo / Condotel in FL, STD-8.1
B28: Vacant Property? | C28: N | D28: G §3.41, §10.17 — refi only, STD-8.5-8.7
B29: Listed for Sale in Last 6 Months? | C29: N | D29: G §11.5 — STD-8.8-8.9
B30: Short-Term Rental? | C30: N | D30: STD-3.12-3.14
B31: Rural / Unique Property? | C31: N | D31: S: Subject Property Location — STD-8.3
B32: Mixed Use / Adult Care / Assisted Living? | C32: N | D32: G §10.7 — STD-8.10
B33: Declining Market? | C33: N | D33: S: Subject Property Location — "-5% CLTV", STD-1.14
A35: 5. DSCR / Income
B36: DSCR Method | C36: Calculated | D36: G §5.32-5.33 — STD-1.5, 3.19
B37: Annual In-Place Rent ($) | C37: 60000 | D37: STD-3.1
B38: Annual Market Rent per 1007/1025 ($) | C38: 58000 | D38: STD-3.1, 3.8
B39: Monthly Principal & Interest ($) | C39: 3200 | D39: STD-3.1 PITIA
B40: Monthly Real Estate Taxes ($) | C40: 450 | D40: STD-3.1 PITIA
B41: Monthly Property Insurance ($) | C41: 150 | D41: STD-3.1 PITIA
B42: Monthly HOA / Association Dues ($) | C42: 0 | D42: STD-3.1 PITIA
B43: Monthly Subordinate Financing Payment ($, if any) | C43: 0 | D43: STD-3.1 — included in DSCR denominator; permissibility per Q-18
A45: 6. Product & Structure
B46: Product Type | C46: 30 Yr Fixed | D46: S: Product Requirements
...

Sheet Sizer
A1: DSCR Loan Sizer
A2: All cells here are formulas driven by the Inputs tab. Do not type over black text.
A4: Computed Parameters
B5: Transaction Purpose | C5: =Inputs!$C$5 -> Purchase
B6: Purpose Index (1=Purchase, 2=R&T, 3=C/O) | C6: =IF(Inputs!$C$5="Purchase",1,IF(Inputs!$C$5="Rate & Term Refinance",2,IF(Inputs!$C$5="Cash-Out Refinance",3,""))) -> 1
B7: Loan Amount Tier | C7: =IF(Inputs!$C$6<=1500000,1,IF(Inputs!$C$6<=2000000,2,IF(Inputs!$C$6<=3000000,3,4))) -> 1 | E7: STD-2.1
B8: Proposed CLTV (Loan Amount ÷ Value) | C8: =Inputs!$C$6/Inputs!$C$7 -> 1.2857143
B9: Base Matrix Cap (Tier × FICO × Purpose) | C9: {=IF($C$7=1,INDEX('Reference Tables'!$B$6:$E$15,MATCH(Inputs!$C$15,INDEX('Reference Tables'!$B$6:$E$15,0,1),1),1+$C$6),IF($C$7=2,INDEX('Reference Tables'!$B$19:$E$28,MATCH(Inputs!$C$15,INDEX('Reference Tables'!$B$19:$E$28,0,1),1),1+$C$6),IF($C$7=3,INDEX('Reference Tables'!$B$32:$E$37,MATCH(Inputs!$C$15,INDEX('Reference Tables'!$B$32:$E$37,0,1),1),1+$C$6),0)))} -> 0.85 | E9: STD-2.1
B10: Annual PITIA (incl. subordinate financing pmt) | C10: =(Inputs!$C$39+Inputs!$C$40+Inputs!$C$41+Inputs!$C$42+Inputs!$C$43)*12 -> 45600 | E10: STD-3.1
B11: Qualifying Rent = lesser of in-place / market rent | C11: =MIN(Inputs!$C$37,Inputs!$C$38) -> 58000 | E11: STD-3.5; Acra may also use higher of actual/market — Q-01
B12: Calculated DSCR | C12: =IF(Inputs!$C$36="No Ratio","N/A - No Ratio",$C$11/$C$10) -> 1.2719298 | E12: STD-3.1
A14: Maximum CLTV Cap Analysis (every applicable cap; lowest one binds)
B15: Condition | C15: Applicable? | D15: Cap — Selected Purpose | E15: Citation
B16: Base Matrix (Loan Tier × FICO × Purpose) | C16: ="Y" -> Y | D16: =IF($C16="Y",$C$9,9.99) -> 0.85 | E16: STD-2.1
B17: Loan Amount < $200,000 | C17: =IF(Inputs!$C$6<200000,"Y","N") -> N | D17: =IF($C17="Y",IF($C$6=1,0.8,0.75),9.99) -> 9.99 | E17: STD-2.5
B18: Property Type Cap (incl. FL -5% adj.) | C18: =IF(OR(Inputs!$C$26="Non-Warrantable Condo",Inputs!$C$26="Condotel/PUDtel",Inputs!$C$26="2-4 Unit",Inputs!$C$26="Manufactured Home"),"Y","N") -> N | D18: {=IF($C18="Y",INDEX('Reference Tables'!$B$41:$G$48,MATCH(Inputs!$C$26,INDEX('Reference Tables'!$B$41:$G$48,0,1),0),1+$C$6)-IF(AND(Inputs!$C$27="Y",INDEX('Reference Tables'!$B$41:$G$48,MATCH(Inputs!$C$26,INDEX('Reference Tables'!$B$41:$G$48,0,1),0),6)="Y"),0.05,0),9.99)} -> 9.99 | E18: STD-8.1
B19: DSCR < 1.0 or No Ratio DSCR | C19: =IF(OR(Inputs!$C$36="No Ratio",AND(Inputs!$C$36="Calculated",ISNUMBER($C$12),$C$12<1)),"Y","N") -> N | D19: =IF($C19="Y",IF($C$6=1,0.75,IF($C$6=2,0.7,0.65)),9.99) -> 9.99 | E19: STD-3.17
B20: Short-Term Rental | C20: =Inputs!$C$30 -> N | D20: =IF($C20="Y",IF($C$6=1,0.75,0.7),9.99) -> 9.99 | E20: STD-3.14
B21: Citizenship Cap (Non-Perm. Resident / Foreign National / ITIN) | C21: =IF(OR(Inputs!$C$12="Non-Permanent Resident",Inputs!$C$12="Foreign National",Inputs!$C$12="ITIN"),"Y","N") -> N | D21: {=IF($C21="Y",IF(Inputs!$C$12="Non-Permanent Resident",0.8,IF(Inputs!$C$12="Foreign National",IF($C$6=1,0.7,0.65),IF(Inputs!$C$12="ITIN",INDEX('Reference Tables'!$B$60:$D$62,MATCH(Inputs!$C$15,INDEX('Reference Tables'!$B$60:$D$62,0,1),1),IF($C$6=1,2,3)),9.99))),9.99)} -> 9.99 | E21: S: Borrower Citizenship; STD-4.3-4.5
B22: 1-or-No Score / Deficient Tradelines | C22: =IF(OR(Inputs!$C$16<=1,AND(Inputs!$C$16=2,Inputs!$C$17="N")),"Y","N") -> N | D22: =IF($C22="Y",0.65,9.99) -> 9.99 | E22: STD-7.3
B23: Mortgage/Rental Housing History | C23: =IF(Inputs!$C$20="Clean / No Restriction","N","Y") -> N | D23: {=IF($C23="Y",INDEX('Reference Tables'!$B$66:$D$70,MATCH(Inputs!$C$20,INDEX('Reference Tables'!$B$66:$D$70,0,1),0),IF($C$6=1,2,3)),9.99)} -> 9.99 | E23: STD-7.9
B24: Bankruptcy / Foreclosure Seasoning | C24: =IF(OR(Inputs!$C$21="N/A - None",Inputs!$C$21="≥36 Mo (No Restriction)"),"N","Y") -> N | D24: {=IF($C24="Y",INDEX('Reference Tables'!$B$74:$D$78,MATCH(Inputs!$C$21,INDEX('Reference Tables'!$B$74:$D$78,0,1),0),IF($C$6=1,2,3)),9.99)} -> 9.99 | E24: STD-7.10
B25: Short Sale / DIL / Modification Seasoning | C25: =IF(OR(Inputs!$C$22="N/A - None",Inputs!$C$22="≥24 Mo (No Restriction)"),"N","Y") -> N | D25: {=IF($C25="Y",INDEX('Reference Tables'!$B$82:$D$85,MATCH(Inputs!$C$22,INDEX('Reference Tables'!$B$82:$D$85,0,1),0),IF($C$6=1,2,3)),9.99)} -> 9.99 | E25: STD-7.11
B26: Rural / Unique Property | C26: =Inputs!$C$31 -> N | D26: =IF($C26="Y",IF($C$6=1,0.8,IF($C$6=2,0.75,0.7)),9.99) -> 9.99 | E26: STD-8.3
B27: First-Time Homebuyer | C27: =Inputs!$C$14 -> N | D27: =IF($C27="Y",0.7,9.99) -> 9.99 | E27: STD-4.10 (flat 70% CLTV, no purpose split)
B28: Vacant Property — Rate & Term Refinance | C28: =IF(AND(Inputs!$C$28="Y",Inputs!$C$5="Rate & Term Refinance"),"Y","N") -> N | D28: =IF($C28="Y",IF(Inputs!$C$6<=1000000,0.7,IF(Inputs!$C$6<=2000000,0.65,9.99)),9.99) -> 9.99 | E28: STD-8.6 (>$2M treatment unstated — flagged below)
B29: Vacant Property — Cash-Out Refinance | C29: =IF(AND(Inputs!$C$28="Y",Inputs!$C$5="Cash-Out Refinance"),"Y","N") -> N | D29: =IF($C29="Y",IF(Inputs!$C$6<1500000,0.6,9.99),9.99) -> 9.99 | E29: STD-8.7 (≥$1.5M treatment unstated — Q-10, flagged below)
B30: Listed for Sale in Last 6 Months | C30: =Inputs!$C$29 -> N | D30: =IF($C30="Y",0.65,9.99) -> 9.99 | E30: STD-8.9 (lesser of appraised value or lowest recent list price)
B31: Escrow Waiver Requested | C31: =Inputs!$C$47 -> N | D31: =IF($C31="Y",0.8,9.99) -> 9.99 | E31: STD-7.12 (also requires FICO≥700, loan≤$1.5M — flagged below)
B33: Final Max CLTV — before Declining-Market adjustment | C33: =MIN(D16:D31) -> 0.85 | E33: Lowest cap above that is Applicable
B34: Declining Market Adjustment | C34: =IF(Inputs!$C$33="Y",-0.05,0) -> 0 | E34: STD-1.14 — "-5% CLTV property/borrower full profile"; combination method per Q-07
B35: FINAL MAX CLTV | C35: =MAX(0,$C$33+$C$34) -> 0.85
A37: Minimum DSCR Requirement (highest applicable trigger governs)
B38: Trigger | C38: Applicable? | D38: Min. DSCR | E38: Citation
B39: Proposed/Final CLTV > 80.00% | C39: =IF(OR($C$8>0.8,$C$35>0.8),"Y","N") -> Y | D39: =IF($C39="Y",1.2,0) -> 1.2 | E39: S: Income Documentation; STD-3.16
B40: Loan Amount > $2,000,000 | C40: =IF(Inputs!$C$6>2000000,"Y","N") -> N | D40: =IF($C40="Y",1,0) -> 0 | E40: STD-2.6
B41: 1-or-No Score / Deficient Tradelines | C41: =IF(OR(Inputs!$C$16<=1,AND(Inputs!$C$16=2,Inputs!$C$17="N")),"Y","N") -> N | D41: =IF($C41="Y",1.1,0) -> 0 | E41: STD-7.3
B42: Rural / Unique Property | C42: =Inputs!$C$31 -> N | D42: =IF($C42="Y",1,0) -> 0 | E42: STD-8.3
B43: Non-Warrantable Condo or Condotel/PUDtel | C43: =IF(OR(Inputs!$C$26="Non-Warrantable Condo",Inputs!$C$26="Condotel/PUDtel"),"Y","N") -> N | D43: =IF($C43="Y",1,0) -> 0 | E43: STD-8.1
B44: First-Time Homebuyer | C44: =Inputs!$C$14 -> N | D44: =IF($C44="Y",1.15,0) -> 0 | E44: STD-4.10
...

Sheet Reference Tables
A1: Reference Tables
A2: Transcribed from the guidelines exactly as printed. The Sizer tab looks these up — edit only if Acra corrects a published figure.
B4: Table 1 — Matrix: Loan Amount ≤ $1,500,000 (STD-2.1)
B5: FICO Min | C5: Purchase | D5: Rate & Term | E5: Cash-Out
B6: 600 | C6: 0.6 | D6: 0.6 | E6: 0.6
B7: 620 | C7: 0.65 | D7: 0.65 | E7: 0.65
B8: 640 | C8: 0.75 | D8: 0.7 | E8: 0.7
B9: 660 | C9: 0.8 | D9: 0.75 | E9: 0.75
B10: 680 | C10: 0.8 | D10: 0.75 | E10: 0.75
B11: 700 | C11: 0.8 | D11: 0.8 | E11: 0.75
B12: 720 | C12: 0.85 | D12: 0.8 | E12: 0.8
B13: 740 | C13: 0.85 | D13: 0.8 | E13: 0.8
B14: 760 | C14: 0.85 | D14: 0.8 | E14: 0.8
B15: 780 | C15: 0.85 | D15: 0.8 | E15: 0.8
B17: Table 2 — Matrix: Loan Amount $1,500,001–$2,000,000 (STD-2.1)
B18: FICO Min | C18: Purchase | D18: Rate & Term | E18: Cash-Out
B19: 300 | C19: 0 | D19: 0 | E19: 0
B20: 620 | C20: 0.65 | D20: 0 | E20: 0
B21: 640 | C21: 0.75 | D21: 0.65 | E21: 0.65
B22: 660 | C22: 0.75 | D22: 0.7 | E22: 0.65
B23: 680 | C23: 0.75 | D23: 0.7 | E23: 0.7
B24: 700 | C24: 0.75 | D24: 0.7 | E24: 0.7
B25: 720 | C25: 0.75 | D25: 0.75 | E25: 0.75
B26: 740 | C26: 0.75 | D26: 0.75 | E26: 0.75
B27: 760 | C27: 0.75 | D27: 0.75 | E27: 0.75
B28: 780 | C28: 0.75 | D28: 0.75 | E28: 0.75
B30: Table 3 — Matrix: Loan Amount $2,000,001–$3,000,000 (STD-2.1)
B31: FICO Min | C31: Purchase | D31: Rate & Term | E31: Cash-Out
B32: 300 | C32: 0 | D32: 0 | E32: 0
B33: 700 | C33: 0.7 | D33: 0.7 | E33: 0.65
B34: 720 | C34: 0.7 | D34: 0.7 | E34: 0.65
B35: 740 | C35: 0.7 | D35: 0.7 | E35: 0.65
B36: 760 | C36: 0.7 | D36: 0.7 | E36: 0.65
B37: 780 | C37: 0.7 | D37: 0.7 | E37: 0.65
B39: Table 4 — Property Type Caps (STD-8.1)
B40: Property Type | C40: Purchase | D40: Rate & Term | E40: Cash-Out | F40: Min DSCR | G40: FL -5% Adj?
B41: SFR | C41: 9.99 | D41: 9.99 | E41: 9.99 | G41: N
B42: Townhome | C42: 9.99 | D42: 9.99 | E42: 9.99 | G42: N
B43: PUD | C43: 9.99 | D43: 9.99 | E43: 9.99 | G43: N
B44: Warrantable Condo | C44: 9.99 | D44: 9.99 | E44: 9.99 | G44: N
...

Sheet Assumptions & Open Items
A1: Assumptions & Open Items
A2: Every Q-item from the guidelines that this sizer's logic had to take a position on. Confirm with Acra before final use.
B4: Q# | C4: Open item (Acra's own wording, abbreviated) | D4: Approach this sizer took
B5: Q-01 | C5: Qualifying rent: lesser of in-place/market, vs. "Acra may use the higher of actual or market rents." | D5: Sizer uses the lesser-of formula (STD-3.5), the more conservative reading. It does not model the higher-of override.
B6: Q-02 | C6: Short-term rental 12-month ledger — how it sets qualifying rent; whether STR caps apply to No Ratio. | D6: Not modeled numerically. STR flag applies the STD-3.14 CLTV/FICO caps regardless of DSCR method; ledger-to-rent conversion is manual.
B7: Q-05 | C7: Housing-history labels (1x30x12 etc.) and BK/FC/short-sale seasoning start/end dates are undefined. | D7: Sizer takes the dropdown selection at face value and applies the printed cap; user must independently determine which bucket applies.
B8: Q-06 | C8: Delayed financing: which matrix column and cash-in-hand rule apply. | D8: Sizer only flags that delayed financing is capped at $1.5MM; it does not reroute the calculation to a different column.
B9: Q-07 | C9: How multiple CLTV caps, adjustments, and reserve triggers combine. | D9: Sizer takes the LOWEST applicable CLTV cap (MIN), the HIGHEST applicable DSCR/FICO/reserve trigger (MAX), and applies the declining-market -5% as a separate subtraction after the CLTV minimum. Reserve triggers are NOT summed/stacked — the largest single trigger governs.
B10: Q-09 | C10: Entity guarantor homeownership requirement vs. first-time-homebuyer allowance. | D10: Both flags are shown independently (FTHB cap/DSCR/FICO applied; entity flag reminds user to confirm guarantor homeownership) — sizer does not resolve the conflict.
B11: Q-10 | C11: Vacant refinance caps above $2M (R/T) or at/above $1.5M (C/O) are unstated. | D11: Sizer shows 9.99 (no numeric cap available) and raises an explicit flag requiring Acra confirmation.
B12: Q-13 | C12: Whether No Ratio is available when another condition carries its own minimum DSCR. | D12: Sizer applies both: if No Ratio is selected, the DSCR test shows N/A, but any other minimum-DSCR trigger still displays for information.
B13: Q-14 | C13: DTI alternatives (40%, 43%) to the stated minimum DSCR on vacant/listed-for-sale/FTHB loans. | D13: Not modeled — DTI is explicitly out of scope per the source document. Only the DSCR-based path is sized.
B14: Q-17 | C14: Matrix labelled CLTV; footnotes and the above-80% rule use LTV. | D14: Sizer treats the single CLTV input as governing both tests, since no subordinate-lien LTV/CLTV split is captured.
B15: Q-18 | C15: Whether/how subordinate financing is permitted. | D15: Sizer includes the subordinate-financing payment in the DSCR denominator per STD-3.1 and raises a flag if a payment is entered, but does not test permissibility.
... B20: Q-27 | C20: Whether every loan on this program is a business-purpose transaction (vs. consumer). | D20: Sizer assumes business-purpose throughout, consistent with the program's "Business Purpose DSCR" listing; consumer-transaction seasoning rules (STD-9.2) are not modeled.
B22: Items not modeled at all (documentation/process items, not numeric caps): entity/trust documentation (§3.12), foreign-national closing docs and AML/OFAC (§3.10), gift-fund documentation (§8.7 balance), DTI-program mechanics (§7.4-7.5), and every item listed in the source document's Appendix B (material referred to but not supplied to the JazzX Team).
